Workbook

Sheet Reajustes
B2: PAINEL DE REAJUSTES — Base: Realizado Superlógica
B3: Edite os percentuais por categoria. Para um item específico, use a tabela debaixo.
B5: ='Previsao Anual'!E122 | D5: ='Resumo Assembleia'!D24
B6: Total Previsto | D6: Taxa Mensal (referência)
B9: REAJUSTE POR CATEGORIA
B10: Categoria | C10: Reajuste %
B11: Despesas Financeiras
B12: Despesa com Funcionários
B13: Retenções Fiscais
B14: Despesa Administrativa
B15: Manutenção
B16: Aquisição de Materiais
B17: Serviços
B18: Investimento e Equipamentos
B19: Taxas e Recolhimentos
B20: REAJUSTE POR ITEM (opcional — sobrescreve a categoria)
B21: Preencha APENAS UMA das 3 opções por item: % (col E), valor anual (col F) ou valor mensal (col G). Prioridade: mensal > anual > %. Vazio = herda o % da categoria.
B22: Item | C22: Categoria | D22: Base Anual (R$) | E22: Reajuste % do Item | F22: Valor Anual 2026 (R$) | G22: Valor Mensal 2026 (R$) | H22: % Aplicado | I22: Valor Final Anual (R$)
B23: Cotas de Capital - Sicoob | C23: Despesas Financeiras | D23: ='Previsao Anual'!C7 | H23: =IFERROR(IF(ISNUMBER(G23),(G23*12)/D23-1,IF(ISNUMBER(F23),F23/D23-1,IF(ISNUMBER(E23),E23,IF(ISNUMBER(C11),C11,0)))),0) | I23: =IF(ISNUMBER(G23),G23*12,IF(ISNUMBER(F23),F23,D23*(1+IF(ISNUMBER(E23),E23,IF(ISNUMBER(C11),C11,0)))))
B24: Reembolso | C24: Despesas Financeiras | D24: ='Previsao Anual'!C8 | H24: =IFERROR(IF(ISNUMBER(G24),(G24*12)/D24-1,IF(ISNUMBER(F24),F24/D24-1,IF(ISNUMBER(E24),E24,IF(ISNUMBER(C11),C11,0)))),0) | I24: =IF(ISNUMBER(G24),G24*12,IF(ISNUMBER(F24),F24,D24*(1+IF(ISNUMBER(E24),E24,IF(ISNUMBER(C11),C11,0)))))
B25: IRRF Poupança | C25: Despesas Financeiras | D25: ='Previsao Anual'!C9 | H25: =IFERROR(IF(ISNUMBER(G25),(G25*12)/D25-1,IF(ISNUMBER(F25),F25/D25-1,IF(ISNUMBER(E25),E25,IF(ISNUMBER(C11),C11,0)))),0) | I25: =IF(ISNUMBER(G25),G25*12,IF(ISNUMBER(F25),F25,D25*(1+IF(ISNUMBER(E25),E25,IF(ISNUMBER(C11),C11,0)))))
B26: Devolução Pagamento Reserva | C26: Despesas Financeiras | D26: ='Previsao Anual'!C10 | H26: =IFERROR(IF(ISNUMBER(G26),(G26*12)/D26-1,IF(ISNUMBER(F26),F26/D26-1,IF(ISNUMBER(E26),E26,IF(ISNUMBER(C11),C11,0)))),0) | I26: =IF(ISNUMBER(G26),G26*12,IF(ISNUMBER(F26),F26,D26*(1+IF(ISNUMBER(E26),E26,IF(ISNUMBER(C11),C11,0)))))
B27: Tarifas Bancárias - Garantidora | C27: Despesas Financeiras | D27: ='Previsao Anual'!C11 | H27: =IFERROR(IF(ISNUMBER(G27),(G27*12)/D27-1,IF(ISNUMBER(F27),F27/D27-1,IF(ISNUMBER(E27),E27,IF(ISNUMBER(C11),C11,0)))),0) | I27: =IF(ISNUMBER(G27),G27*12,IF(ISNUMBER(F27),F27,D27*(1+IF(ISNUMBER(E27),E27,IF(ISNUMBER(C11),C11,0)))))
B28: Contrato Mão de Obra Terceirizada | C28: Despesa com Funcionários | D28: ='Previsao Anual'!C15 | H28: =IFERROR(IF(ISNUMBER(G28),(G28*12)/D28-1,IF(ISNUMBER(F28),F28/D28-1,IF(ISNUMBER(E28),E28,IF(ISNUMBER(C12),C12,0)))),0) | I28: =IF(ISNUMBER(G28),G28*12,IF(ISNUMBER(F28),F28,D28*(1+IF(ISNUMBER(E28),E28,IF(ISNUMBER(C12),C12,0)))))
B29: Alimentação e Lanche | C29: Despesa com Funcionários | D29: ='Previsao Anual'!C16 | H29: =IFERROR(IF(ISNUMBER(G29),(G29*12)/D29-1,IF(ISNUMBER(F29),F29/D29-1,IF(ISNUMBER(E29),E29,IF(ISNUMBER(C12),C12,0)))),0) | I29: =IF(ISNUMBER(G29),G29*12,IF(ISNUMBER(F29),F29,D29*(1+IF(ISNUMBER(E29),E29,IF(ISNUMBER(C12),C12,0)))))
B30: Padaria | C30: Despesa com Funcionários | D30: ='Previsao Anual'!C17 | H30: =IFERROR(IF(ISNUMBER(G30),(G30*12)/D30-1,IF(ISNUMBER(F30),F30/D30-1,IF(ISNUMBER(E30),E30,IF(ISNUMBER(C12),C12,0)))),0) | I30: =IF(ISNUMBER(G30),G30*12,IF(ISNUMBER(F30),F30,D30*(1+IF(ISNUMBER(E30),E30,IF(ISNUMBER(C12),C12,0)))))
B31: ISS | C31: Retenções Fiscais | D31: ='Previsao Anual'!C21 | H31: =IFERROR(IF(ISNUMBER(G31),(G31*12)/D31-1,IF(ISNUMBER(F31),F31/D31-1,IF(ISNUMBER(E31),E31,IF(ISNUMBER(C13),C13,0)))),0) | I31: =IF(ISNUMBER(G31),G31*12,IF(ISNUMBER(F31),F31,D31*(1+IF(ISNUMBER(E31),E31,IF(ISNUMBER(C13),C13,0)))))
B32: DARF Pis Cofins CSLL | C32: Retenções Fiscais | D32: ='Previsao Anual'!C22 | H32: =IFERROR(IF(ISNUMBER(G32),(G32*12)/D32-1,IF(ISNUMBER(F32),F32/D32-1,IF(ISNUMBER(E32),E32,IF(ISNUMBER(C13),C13,0)))),0) | I32: =IF(ISNUMBER(G32),G32*12,IF(ISNUMBER(F32),F32,D32*(1+IF(ISNUMBER(E32),E32,IF(ISNUMBER(C13),C13,0)))))
B33: Honorários Administrativos | C33: Despesa Administrativa | D33: ='Previsao Anual'!C26 | H33: =IFERROR(IF(ISNUMBER(G33),(G33*12)/D33-1,IF(ISNUMBER(F33),F33/D33-1,IF(ISNUMBER(E33),E33,IF(ISNUMBER(C14),C14,0)))),0) | I33: =IF(ISNUMBER(G33),G33*12,IF(ISNUMBER(F33),F33,D33*(1+IF(ISNUMBER(E33),E33,IF(ISNUMBER(C14),C14,0)))))
B34: Honorários Síndico | C34: Despesa Administrativa | D34: ='Previsao Anual'!C27 | H34: =IFERROR(IF(ISNUMBER(G34),(G34*12)/D34-1,IF(ISNUMBER(F34),F34/D34-1,IF(ISNUMBER(E34),E34,IF(ISNUMBER(C14),C14,0)))),0) | I34: =IF(ISNUMBER(G34),G34*12,IF(ISNUMBER(F34),F34,D34*(1+IF(ISNUMBER(E34),E34,IF(ISNUMBER(C14),C14,0)))))
B35: Despesas Com Correios | C35: Despesa Administrativa | D35: ='Previsao Anual'!C28 | H35: =IFERROR(IF(ISNUMBER(G35),(G35*12)/D35-1,IF(ISNUMBER(F35),F35/D35-1,IF(ISNUMBER(E35),E35,IF(ISNUMBER(C14),C14,0)))),0) | I35: =IF(ISNUMBER(G35),G35*12,IF(ISNUMBER(F35),F35,D35*(1+IF(ISNUMBER(E35),E35,IF(ISNUMBER(C14),C14,0)))))
B36: Despesas Com Cartório | C36: Despesa Administrativa | D36: ='Previsao Anual'!C29 | H36: =IFERROR(IF(ISNUMBER(G36),(G36*12)/D36-1,IF(ISNUMBER(F36),F36/D36-1,IF(ISNUMBER(E36),E36,IF(ISNUMBER(C14),C14,0)))),0) | I36: =IF(ISNUMBER(G36),G36*12,IF(ISNUMBER(F36),F36,D36*(1+IF(ISNUMBER(E36),E36,IF(ISNUMBER(C14),C14,0)))))
B37: Despesas Com Material de Expediente | C37: Despesa Administrativa | D37: ='Previsao Anual'!C30 | H37: =IFERROR(IF(ISNUMBER(G37),(G37*12)/D37-1,IF(ISNUMBER(F37),F37/D37-1,IF(ISNUMBER(E37),E37,IF(ISNUMBER(C14),C14,0)))),0) | I37: =IF(ISNUMBER(G37),G37*12,IF(ISNUMBER(F37),F37,D37*(1+IF(ISNUMBER(E37),E37,IF(ISNUMBER(C14),C14,0)))))
B38: Honorários Advocatícios | C38: Despesa Administrativa | D38: ='Previsao Anual'!C31 | H38: =IFERROR(IF(ISNUMBER(G38),(G38*12)/D38-1,IF(ISNUMBER(F38),F38/D38-1,IF(ISNUMBER(E38),E38,IF(ISNUMBER(C14),C14,0)))),0) | I38: =IF(ISNUMBER(G38),G38*12,IF(ISNUMBER(F38),F38,D38*(1+IF(ISNUMBER(E38),E38,IF(ISNUMBER(C14),C14,0)))))
B39: Custas Processuais | C39: Despesa Administrativa | D39: ='Previsao Anual'!C32 | H39: =IFERROR(IF(ISNUMBER(G39),(G39*12)/D39-1,IF(ISNUMBER(F39),F39/D39-1,IF(ISNUMBER(E39),E39,IF(ISNUMBER(C14),C14,0)))),0) | I39: =IF(ISNUMBER(G39),G39*12,IF(ISNUMBER(F39),F39,D39*(1+IF(ISNUMBER(E39),E39,IF(ISNUMBER(C14),C14,0)))))
B40: Multa-Penalidade | C40: Despesa Administrativa | D40: ='Previsao Anual'!C33 | H40: =IFERROR(IF(ISNUMBER(G40),(G40*12)/D40-1,IF(ISNUMBER(F40),F40/D40-1,IF(ISNUMBER(E40),E40,IF(ISNUMBER(C14),C14,0)))),0) | I40: =IF(ISNUMBER(G40),G40*12,IF(ISNUMBER(F40),F40,D40*(1+IF(ISNUMBER(E40),E40,IF(ISNUMBER(C14),C14,0)))))
B41: Taxa Antecipação Garantidora | C41: Despesa Administrativa | D41: ='Previsao Anual'!C34 | H41: =IFERROR(IF(ISNUMBER(G41),(G41*12)/D41-1,IF(ISNUMBER(F41),F41/D41-1,IF(ISNUMBER(E41),E41,IF(ISNUMBER(C14),C14,0)))),0) | I41: =IF(ISNUMBER(G41),G41*12,IF(ISNUMBER(F41),F41,D41*(1+IF(ISNUMBER(E41),E41,IF(ISNUMBER(C14),C14,0)))))
B42: Despesa com Deslocamento | C42: Despesa Administrativa | D42: ='Previsao Anual'!C35 | H42: =IFERROR(IF(ISNUMBER(G42),(G42*12)/D42-1,IF(ISNUMBER(F42),F42/D42-1,IF(ISNUMBER(E42),E42,IF(ISNUMBER(C14),C14,0)))),0) | I42: =IF(ISNUMBER(G42),G42*12,IF(ISNUMBER(F42),F42,D42*(1+IF(ISNUMBER(E42),E42,IF(ISNUMBER(C14),C14,0)))))
B43: Contrato Manutenção Elevador | C43: Manutenção | D43: ='Previsao Anual'!C39 | H43: =IFERROR(IF(ISNUMBER(G43),(G43*12)/D43-1,IF(ISNUMBER(F43),F43/D43-1,IF(ISNUMBER(E43),E43,IF(ISNUMBER(C15),C15,0)))),0) | I43: =IF(ISNUMBER(G43),G43*12,IF(ISNUMBER(F43),F43,D43*(1+IF(ISNUMBER(E43),E43,IF(ISNUMBER(C15),C15,0)))))
B44: Contrato Manutenção Piscina | C44: Manutenção | D44: ='Previsao Anual'!C40 | H44: =IFERROR(IF(ISNUMBER(G44),(G44*12)/D44-1,IF(ISNUMBER(F44),F44/D44-1,IF(ISNUMBER(E44),E44,IF(ISNUMBER(C15),C15,0)))),0) | I44: =IF(ISNUMBER(G44),G44*12,IF(ISNUMBER(F44),F44,D44*(1+IF(ISNUMBER(E44),E44,IF(ISNUMBER(C15),C15,0)))))
...

Sheet Previsao Anual
B2: PREVISÃO ANUAL 2026
B3: Os percentuais vêm da aba 'Reajustes'. Não edite nada aqui — só visualize.
B5: Item | C5: Base Anual (R$) | D5: Reajuste % | E5: Previsão 2026 (R$) | F5: Mensal (R$)
B6: Despesas Financeiras
B7: Cotas de Capital - Sicoob | C7: 60 | D7: =Reajustes!H23 | E7: =Reajustes!I23 | F7: =E7/12
B8: Reembolso | C8: 193.15 | D8: =Reajustes!H24 | E8: =Reajustes!I24 | F8: =E8/12
B9: IRRF Poupança | C9: 5577.22 | D9: =Reajustes!H25 | E9: =Reajustes!I25 | F9: =E9/12
B10: Devolução Pagamento Reserva | C10: 279.49 | D10: =Reajustes!H26 | E10: =Reajustes!I26 | F10: =E10/12
B11: Tarifas Bancárias - Garantidora | C11: 7260 | D11: =Reajustes!H27 | E11: =Reajustes!I27 | F11: =E11/12
B12: Total Despesas Financeiras | C12: =SUM(C7:C11) | E12: =SUM(E7:E11) | F12: =E12/12
B14: Despesa com Funcionários
B15: Contrato Mão de Obra Terceirizada | C15: 590090.19 | D15: =Reajustes!H28 | E15: =Reajustes!I28 | F15: =E15/12
B16: Alimentação e Lanche | C16: 2298.02 | D16: =Reajustes!H29 | E16: =Reajustes!I29 | F16: =E16/12
B17: Padaria | C17: 1755.44 | D17: =Reajustes!H30 | E17: =Reajustes!I30 | F17: =E17/12
B18: Total Despesa com Funcionários | C18: =SUM(C15:C17) | E18: =SUM(E15:E17) | F18: =E18/12
B20: Retenções Fiscais
B21: ISS | C21: 45080.18 | D21: =Reajustes!H31 | E21: =Reajustes!I31 | F21: =E21/12
B22: DARF Pis Cofins CSLL | C22: 93567.39 | D22: =Reajustes!H32 | E22: =Reajustes!I32 | F22: =E22/12
B23: Total Retenções Fiscais | C23: =SUM(C21:C22) | E23: =SUM(E21:E22) | F23: =E23/12
B25: Despesa Administrativa
B26: Honorários Administrativos | C26: 22442 | D26: =Reajustes!H33 | E26: =Reajustes!I33 | F26: =E26/12
B27: Honorários Síndico | C27: 38400 | D27: =Reajustes!H34 | E27: =Reajustes!I34 | F27: =E27/12
B28: Despesas Com Correios | C28: 133 | D28: =Reajustes!H35 | E28: =Reajustes!I35 | F28: =E28/12
B29: Despesas Com Cartório | C29: 718.72 | D29: =Reajustes!H36 | E29: =Reajustes!I36 | F29: =E29/12
B30: Despesas Com Material de Expediente | C30: 734.92 | D30: =Reajustes!H37 | E30: =Reajustes!I37 | F30: =E30/12
B31: Honorários Advocatícios | C31: 15939 | D31: =Reajustes!H38 | E31: =Reajustes!I38 | F31: =E31/12
B32: Custas Processuais | C32: 1013.32 | D32: =Reajustes!H39 | E32: =Reajustes!I39 | F32: =E32/12
B33: Multa-Penalidade | C33: 22.3 | D33: =Reajustes!H40 | E33: =Reajustes!I40 | F33: =E33/12
B34: Taxa Antecipação Garantidora | C34: 38918.44 | D34: =Reajustes!H41 | E34: =Reajustes!I41 | F34: =E34/12
B35: Despesa com Deslocamento | C35: 30.63 | D35: =Reajustes!H42 | E35: =Reajustes!I42 | F35: =E35/12
B36: Total Despesa Administrativa | C36: =SUM(C26:C35) | E36: =SUM(E26:E35) | F36: =E36/12
B38: Manutenção
B39: Contrato Manutenção Elevador | C39: 17433.48 | D39: =Reajustes!H43 | E39: =Reajustes!I43 | F39: =E39/12
B40: Contrato Manutenção Piscina | C40: 18084 | D40: =Reajustes!H44 | E40: =Reajustes!I44 | F40: =E40/12
B41: Contrato Manutenção Jardinagem | C41: 9775 | D41: =Reajustes!H45 | E41: =Reajustes!I45 | F41: =E41/12
B42: Contrato Manutenção Segurança Eletrônica | C42: 15416.46 | D42: =Reajustes!H46 | E42: =Reajustes!I46 | F42: =E42/12
B43: Contrato de Manutenção de Desinsetização | C43: 6633.73 | D43: =Reajustes!H47 | E43: =Reajustes!I47 | F43: =E43/12
B44: Contrato Manutenção de Segurança | C44: 819.28 | D44: =Reajustes!H48 | E44: =Reajustes!I48 | F44: =E44/12
B45: Contrato Manutenção Bombas | C45: 3430.94 | D45: =Reajustes!H49 | E45: =Reajustes!I49 | F45: =E45/12
B46: Contrato Cx. de Gordura - Fossa e Esgoto | C46: 13159.4 | D46: =Reajustes!H50 | E46: =Reajustes!I50 | F46: =E46/12
...

Sheet Previsao Mensal
B2: PREVISÃO MENSAL 2026
B3: Valores mensais já com reajuste aplicado. Os percentuais vêm da aba 'Reajustes'.
B5: Item | C5: Jan/26 | D5: Fev/26 | E5: Mar/26 | F5: Abr/26 | G5: Mai/26 | H5: Jun/26 | I5: Jul/26 | J5: Ago/26 | K5: Set/26 | L5: Out/26 | M5: Nov/26 | N5: Dez/26 | O5: Total Anual
B6: Despesas Financeiras
B7: Cotas de Capital - Sicoob | C7: =0.0*(1+Reajustes!H23) | D7: =0.0*(1+Reajustes!H23) | E7: =0.0*(1+Reajustes!H23) | F7: =0.0*(1+Reajustes!H23) | G7: =0.0*(1+Reajustes!H23) | H7: =0.0*(1+Reajustes!H23) | I7: =0.0*(1+Reajustes!H23) | J7: =0.0*(1+Reajustes!H23) | K7: =0.0*(1+Reajustes!H23) | L7: =0.0*(1+Reajustes!H23) | M7: =0.0*(1+Reajustes!H23) | N7: =60.0*(1+Reajustes!H23) | O7: =SUM(C7:N7)
B8: Reembolso | C8: =0.0*(1+Reajustes!H24) | D8: =0.0*(1+Reajustes!H24) | E8: =62.11*(1+Reajustes!H24) | F8: =0.0*(1+Reajustes!H24) | G8: =31.05*(1+Reajustes!H24) | H8: =0.0*(1+Reajustes!H24) | I8: =0.0*(1+Reajustes!H24) | J8: =99.99*(1+Reajustes!H24) | K8: =0.0*(1+Reajustes!H24) | L8: =0.0*(1+Reajustes!H24) | M8: =0.0*(1+Reajustes!H24) | N8: =0.0*(1+Reajustes!H24) | O8: =SUM(C8:N8)
B9: IRRF Poupança | C9: =528.32*(1+Reajustes!H25) | D9: =579.8*(1+Reajustes!H25) | E9: =645.55*(1+Reajustes!H25) | F9: =692.6*(1+Reajustes!H25) | G9: =732.26*(1+Reajustes!H25) | H9: =787.2*(1+Reajustes!H25) | I9: =0.0*(1+Reajustes!H25) | J9: =558.95*(1+Reajustes!H25) | K9: =344.95*(1+Reajustes!H25) | L9: =339.15*(1+Reajustes!H25) | M9: =368.44*(1+Reajustes!H25) | N9: =0.0*(1+Reajustes!H25) | O9: =SUM(C9:N9)
B10: Devolução Pagamento Reserva | C10: =0.0*(1+Reajustes!H26) | D10: =0.0*(1+Reajustes!H26) | E10: =62.11*(1+Reajustes!H26) | F10: =62.11*(1+Reajustes!H26) | G10: =0.0*(1+Reajustes!H26) | H10: =31.05*(1+Reajustes!H26) | I10: =0.0*(1+Reajustes!H26) | J10: =0.0*(1+Reajustes!H26) | K10: =62.11*(1+Reajustes!H26) | L10: =0.0*(1+Reajustes!H26) | M10: =62.11*(1+Reajustes!H26) | N10: =0.0*(1+Reajustes!H26) | O10: =SUM(C10:N10)
B11: Tarifas Bancárias - Garantidora | C11: =660.0*(1+Reajustes!H27) | D11: =660.0*(1+Reajustes!H27) | E11: =660.0*(1+Reajustes!H27) | F11: =660.0*(1+Reajustes!H27) | G11: =660.0*(1+Reajustes!H27) | H11: =660.0*(1+Reajustes!H27) | I11: =660.0*(1+Reajustes!H27) | J11: =660.0*(1+Reajustes!H27) | K11: =660.0*(1+Reajustes!H27) | L11: =660.0*(1+Reajustes!H27) | M11: =660.0*(1+Reajustes!H27) | N11: =0.0*(1+Reajustes!H27) | O11: =SUM(C11:N11)
B12: Total Despesas Financeiras | C12: =SUM(C7:C11) | D12: =SUM(D7:D11) | E12: =SUM(E7:E11) | F12: =SUM(F7:F11) | G12: =SUM(G7:G11) | H12: =SUM(H7:H11) | I12: =SUM(I7:I11) | J12: =SUM(J7:J11) | ... O12: =SUM(O7:O11)
B14: Despesa com Funcionários
B15: Contrato Mão de Obra Terceirizada | C15: =55556.6*(1+Reajustes!H28) | D15: =57451.76*(1+Reajustes!H28) | E15: =57451.76*(1+Reajustes!H28) | F15: =57451.76*(1+Reajustes!H28) | G15: =36676.66*(1+Reajustes!H28) | H15: =0.0*(1+Reajustes!H28) | I15: =126672.42*(1+Reajustes!H28) | J15: =58223.72*(1+Reajustes!H28) | K15: =44218.15*(1+Reajustes!H28) | L15: =41597.04*(1+Reajustes!H28) | M15: =54790.32*(1+Reajustes!H28) | N15: =0.0*(1+Reajustes!H28) | O15: =SUM(C15:N15)
B16: Alimentação e Lanche | C16: =427.51*(1+Reajustes!H29) | D16: =275.15*(1+Reajustes!H29) | E16: =300.8*(1+Reajustes!H29) | F16: =282.0*(1+Reajustes!H29) | G16: =253.6*(1+Reajustes!H29) | H16: =458.16*(1+Reajustes!H29) | I16: =300.8*(1+Reajustes!H29) | J16: =0.0*(1+Reajustes!H29) | K16: =0.0*(1+Reajustes!H29) | L16: =0.0*(1+Reajustes!H29) | M16: =0.0*(1+Reajustes!H29) | N16: =0.0*(1+Reajustes!H29) | O16: =SUM(C16:N16)
B17: Padaria | C17: =0.0*(1+Reajustes!H30) | D17: =0.0*(1+Reajustes!H30) | E17: =0.0*(1+Reajustes!H30) | F17: =0.0*(1+Reajustes!H30) | G17: =0.0*(1+Reajustes!H30) | H17: =0.0*(1+Reajustes!H30) | I17: =0.0*(1+Reajustes!H30) | J17: =418.0*(1+Reajustes!H30) | K17: =286.39*(1+Reajustes!H30) | L17: =325.1*(1+Reajustes!H30) | M17: =470.2*(1+Reajustes!H30) | N17: =255.75*(1+Reajustes!H30) | O17: =SUM(C17:N17)
B18: Total Despesa com Funcionários | C18: =SUM(C15:C17) | D18: =SUM(D15:D17) | E18: =SUM(E15:E17) | F18: =SUM(F15:F17) | G18: =SUM(G15:G17) | H18: =SUM(H15:H17) | I18: =SUM(I15:I17) | J18: =SUM(J15:J17) | ... O18: =SUM(O15:O17)
B20: Retenções Fiscais
B21: ISS | C21: =3623.35*(1+Reajustes!H31) | D21: =5216.74*(1+Reajustes!H31) | E21: =5333.58*(1+Reajustes!H31) | F21: =3815.81*(1+Reajustes!H31) | G21: =3801.31*(1+Reajustes!H31) | H21: =3744.21*(1+Reajustes!H31) | I21: =579.45*(1+Reajustes!H31) | J21: =4901.8*(1+Reajustes!H31) | K21: =3276.3*(1+Reajustes!H31) | L21: =2817.56*(1+Reajustes!H31) | M21: =3150.41*(1+Reajustes!H31) | N21: =4819.66*(1+Reajustes!H31) | O21: =SUM(C21:N21)
B22: DARF Pis Cofins CSLL | C22: =9758.73*(1+Reajustes!H32) | D22: =9225.67*(1+Reajustes!H32) | E22: =6141.35*(1+Reajustes!H32) | F22: =6039.63*(1+Reajustes!H32) | G22: =6041.45*(1+Reajustes!H32) | H22: =1164.67*(1+Reajustes!H32) | I22: =6718.67*(1+Reajustes!H32) | J22: =9371.71*(1+Reajustes!H32) | K22: =9375.14*(1+Reajustes!H32) | L22: =9373.94*(1+Reajustes!H32) | M22: =8378.55*(1+Reajustes!H32) | N22: =11977.88*(1+Reajustes!H32) | O22: =SUM(C22:N22)
B23: Total Retenções Fiscais | C23: =SUM(C21:C22) | D23: =SUM(D21:D22) | E23: =SUM(E21:E22) | F23: =SUM(F21:F22) | G23: =SUM(G21:G22) | H23: =SUM(H21:H22) | I23: =SUM(I21:I22) | J23: =SUM(J21:J22) | ... O23: =SUM(O21:O22)
B25: Despesa Administrativa
B26: Honorários Administrativos | C26: =1862.0*(1+Reajustes!H33) | D26: =1862.0*(1+Reajustes!H33) | E26: =1862.0*(1+Reajustes!H33) | F26: =1862.0*(1+Reajustes!H33) | G26: =1862.0*(1+Reajustes!H33) | H26: =1862.0*(1+Reajustes!H33) | I26: =1862.0*(1+Reajustes!H33) | J26: =1862.0*(1+Reajustes!H33) | K26: =1862.0*(1+Reajustes!H33) | L26: =1862.0*(1+Reajustes!H33) | M26: =1862.0*(1+Reajustes!H33) | N26: =1960.0*(1+Reajustes!H33) | O26: =SUM(C26:N26)
B27: Honorários Síndico | C27: =3200.0*(1+Reajustes!H34) | D27: =3200.0*(1+Reajustes!H34) | E27: =3200.0*(1+Reajustes!H34) | F27: =3200.0*(1+Reajustes!H34) | G27: =3200.0*(1+Reajustes!H34) | H27: =3200.0*(1+Reajustes!H34) | I27: =3200.0*(1+Reajustes!H34) | J27: =3200.0*(1+Reajustes!H34) | K27: =3200.0*(1+Reajustes!H34) | L27: =3200.0*(1+Reajustes!H34) | M27: =3200.0*(1+Reajustes!H34) | N27: =3200.0*(1+Reajustes!H34) | O27: =SUM(C27:N27)
B28: Despesas Com Correios | C28: =0.0*(1+Reajustes!H35) | D28: =114.6*(1+Reajustes!H35) | E28: =18.4*(1+Reajustes!H35) | F28: =0.0*(1+Reajustes!H35) | G28: =0.0*(1+Reajustes!H35) | H28: =0.0*(1+Reajustes!H35) | I28: =0.0*(1+Reajustes!H35) | J28: =0.0*(1+Reajustes!H35) | K28: =0.0*(1+Reajustes!H35) | L28: =0.0*(1+Reajustes!H35) | M28: =0.0*(1+Reajustes!H35) | N28: =0.0*(1+Reajustes!H35) | O28: =SUM(C28:N28)
B29: Despesas Com Cartório | C29: =0.0*(1+Reajustes!H36) | D29: =114.6*(1+Reajustes!H36) | E29: =0.0*(1+Reajustes!H36) | F29: =342.96*(1+Reajustes!H36) | G29: =0.0*(1+Reajustes!H36) | H29: =161.25*(1+Reajustes!H36) | I29: =99.91*(1+Reajustes!H36) | J29: =0.0*(1+Reajustes!H36) | K29: =0.0*(1+Reajustes!H36) | L29: =0.0*(1+Reajustes!H36) | M29: =0.0*(1+Reajustes!H36) | N29: =0.0*(1+Reajustes!H36) | O29: =SUM(C29:N29)
B30: Despesas Com Material de Expediente | C30: =0.0*(1+Reajustes!H37) | D30: =0.0*(1+Reajustes!H37) | E30: =263.34*(1+Reajustes!H37) | F30: =0.0*(1+Reajustes!H37) | G30: =0.0*(1+Reajustes!H37) | H30: =471.58*(1+Reajustes!H37) | I30: =0.0*(1+Reajustes!H37) | J30: =0.0*(1+Reajustes!H37) | K30: =0.0*(1+Reajustes!H37) | L30: =0.0*(1+Reajustes!H37) | M30: =0.0*(1+Reajustes!H37) | N30: =0.0*(1+Reajustes!H37) | O30: =SUM(C30:N30)
B31: Honorários Advocatícios | C31: =0.0*(1+Reajustes!H38) | D31: =759.0*(1+Reajustes!H38) | E31: =1518.0*(1+Reajustes!H38) | F31: =1518.0*(1+Reajustes!H38) | G31: =1518.0*(1+Reajustes!H38) | H31: =1518.0*(1+Reajustes!H38) | I31: =1518.0*(1+Reajustes!H38) | J31: =1518.0*(1+Reajustes!H38) | K31: =1518.0*(1+Reajustes!H38) | L31: =1518.0*(1+Reajustes!H38) | M31: =1518.0*(1+Reajustes!H38) | N31: =1518.0*(1+Reajustes!H38) | O31: =SUM(C31:N31)
B32: Custas Processuais | C32: =0.0*(1+Reajustes!H39) | D32: =0.0*(1+Reajustes!H39) | E32: =0.0*(1+Reajustes!H39) | F32: =0.0*(1+Reajustes!H39) | G32: =0.0*(1+Reajustes!H39) | H32: =0.0*(1+Reajustes!H39) | I32: =112.28*(1+Reajustes!H39) | J32: =404.74*(1+Reajustes!H39) | K32: =91.56*(1+Reajustes!H39) | L32: =404.74*(1+Reajustes!H39) | M32: =0.0*(1+Reajustes!H39) | N32: =0.0*(1+Reajustes!H39) | O32: =SUM(C32:N32)
B33: Multa-Penalidade | C33: =0.0*(1+Reajustes!H40) | D33: =0.0*(1+Reajustes!H40) | E33: =0.0*(1+Reajustes!H40) | F33: =0.0*(1+Reajustes!H40) | G33: =0.0*(1+Reajustes!H40) | H33: =0.0*(1+Reajustes!H40) | I33: =0.0*(1+Reajustes!H40) | J33: =0.0*(1+Reajustes!H40) | K33: =0.0*(1+Reajustes!H40) | L33: =22.3*(1+Reajustes!H40) | M33: =0.0*(1+Reajustes!H40) | N33: =0.0*(1+Reajustes!H40) | O33: =SUM(C33:N33)
B34: Taxa Antecipação Garantidora | C34: =2939.58*(1+Reajustes!H41) | D34: =3678.04*(1+Reajustes!H41) | E34: =3514.94*(1+Reajustes!H41) | F34: =3459.27*(1+Reajustes!H41) | G34: =3540.76*(1+Reajustes!H41) | H34: =3601.87*(1+Reajustes!H41) | I34: =3601.8*(1+Reajustes!H41) | J34: =3671.78*(1+Reajustes!H41) | K34: =3647.33*(1+Reajustes!H41) | L34: =3577.78*(1+Reajustes!H41) | M34: =3685.29*(1+Reajustes!H41) | N34: =0.0*(1+Reajustes!H41) | O34: =SUM(C34:N34)
B35: Despesa com Deslocamento | C35: =0.0*(1+Reajustes!H42) | D35: =0.0*(1+Reajustes!H42) | E35: =30.63*(1+Reajustes!H42) | F35: =0.0*(1+Reajustes!H42) | G35: =0.0*(1+Reajustes!H42) | H35: =0.0*(1+Reajustes!H42) | I35: =0.0*(1+Reajustes!H42) | J35: =0.0*(1+Reajustes!H42) | K35: =0.0*(1+Reajustes!H42) | L35: =0.0*(1+Reajustes!H42) | M35: =0.0*(1+Reajustes!H42) | N35: =0.0*(1+Reajustes!H42) | O35: =SUM(C35:N35)
B36: Total Despesa Administrativa | C36: =SUM(C26:C35) | D36: =SUM(D26:D35) | E36: =SUM(E26:E35) | F36: =SUM(F26:F35) | G36: =SUM(G26:G35) | H36: =SUM(H26:H35) | I36: =SUM(I26:I35) | J36: =SUM(J26:J35) | ... O36: =SUM(O26:O35)
B38: Manutenção
B39: Contrato Manutenção Elevador | C39: =1452.79*(1+Reajustes!H43) | D39: =1452.79*(1+Reajustes!H43) | E39: =1452.79*(1+Reajustes!H43) | F39: =1452.79*(1+Reajustes!H43) | G39: =1452.79*(1+Reajustes!H43) | H39: =1452.79*(1+Reajustes!H43) | I39: =1452.79*(1+Reajustes!H43) | J39: =1452.79*(1+Reajustes!H43) | K39: =1452.79*(1+Reajustes!H43) | L39: =1452.79*(1+Reajustes!H43) | M39: =1452.79*(1+Reajustes!H43) | N39: =1452.79*(1+Reajustes!H43) | O39: =SUM(C39:N39)
B40: Contrato Manutenção Piscina | C40: =1500.0*(1+Reajustes!H44) | D40: =1800.0*(1+Reajustes!H44) | E40: =1500.0*(1+Reajustes!H44) | F40: =1500.0*(1+Reajustes!H44) | G40: =1500.0*(1+Reajustes!H44) | H40: =1500.0*(1+Reajustes!H44) | I40: =1500.0*(1+Reajustes!H44) | J40: =1500.0*(1+Reajustes!H44) | K40: =1446.0*(1+Reajustes!H44) | L40: =1446.0*(1+Reajustes!H44) | M40: =1446.0*(1+Reajustes!H44) | N40: =1446.0*(1+Reajustes!H44) | O40: =SUM(C40:N40)
B41: Contrato Manutenção Jardinagem | C41: =1100.0*(1+Reajustes!H45) | D41: =1100.0*(1+Reajustes!H45) | E41: =1100.0*(1+Reajustes!H45) | F41: =1100.0*(1+Reajustes!H45) | G41: =1045.0*(1+Reajustes!H45) | H41: =1045.0*(1+Reajustes!H45) | I41: =1045.0*(1+Reajustes!H45) | J41: =1100.0*(1+Reajustes!H45) | K41: =0.0*(1+Reajustes!H45) | L41: =0.0*(1+Reajustes!H45) | M41: =0.0*(1+Reajustes!H45) | N41: =1140.0*(1+Reajustes!H45) | O41: =SUM(C41:N41)
B42: Contrato Manutenção Segurança Eletrônica | C42: =820.0*(1+Reajustes!H46) | D42: =886.54*(1+Reajustes!H46) | E42: =1400.0*(1+Reajustes!H46) | F42: =1400.0*(1+Reajustes!H46) | G42: =1355.48*(1+Reajustes!H46) | H42: =1355.48*(1+Reajustes!H46) | I42: =1355.48*(1+Reajustes!H46) | J42: =1355.48*(1+Reajustes!H46) | K42: =1372.0*(1+Reajustes!H46) | L42: =1372.0*(1+Reajustes!H46) | M42: =1372.0*(1+Reajustes!H46) | N42: =1372.0*(1+Reajustes!H46) | O42: =SUM(C42:N42)
B43: Contrato de Manutenção de Desinsetização | C43: =0.0*(1+Reajustes!H47) | D43: =604.33*(1+Reajustes!H47) | E43: =604.33*(1+Reajustes!H47) | F43: =604.33*(1+Reajustes!H47) | G43: =604.33*(1+Reajustes!H47) | H43: =604.33*(1+Reajustes!H47) | I43: =604.33*(1+Reajustes!H47) | J43: =601.55*(1+Reajustes!H47) | K43: =601.55*(1+Reajustes!H47) | L43: =601.55*(1+Reajustes!H47) | M43: =601.55*(1+Reajustes!H47) | N43: =601.55*(1+Reajustes!H47) | O43: =SUM(C43:N43)
B44: Contrato Manutenção de Segurança | C44: =615.68*(1+Reajustes!H48) | D44: =0.0*(1+Reajustes!H48) | E44: =0.0*(1+Reajustes!H48) | F44: =203.6*(1+Reajustes!H48) | G44: =0.0*(1+Reajustes!H48) | H44: =0.0*(1+Reajustes!H48) | I44: =0.0*(1+Reajustes!H48) | J44: =0.0*(1+Reajustes!H48) | K44: =0.0*(1+Reajustes!H48) | L44: =0.0*(1+Reajustes!H48) | M44: =0.0*(1+Reajustes!H48) | N44: =0.0*(1+Reajustes!H48) | O44: =SUM(C44:N44)
B45: Contrato Manutenção Bombas | C45: =282.17*(1+Reajustes!H49) | D45: =305.68*(1+Reajustes!H49) | E45: =305.81*(1+Reajustes!H49) | F45: =281.85*(1+Reajustes!H49) | G45: =281.91*(1+Reajustes!H49) | H45: =281.85*(1+Reajustes!H49) | I45: =282.0*(1+Reajustes!H49) | J45: =282.0*(1+Reajustes!H49) | K45: =281.91*(1+Reajustes!H49) | L45: =282.0*(1+Reajustes!H49) | M45: =281.82*(1+Reajustes!H49) | N45: =281.94*(1+Reajustes!H49) | O45: =SUM(C45:N45)
B46: Contrato Cx. de Gordura - Fossa e Esgoto | C46: =967.6*(1+Reajustes!H50) | D46: =0.0*(1+Reajustes!H50) | E46: =2085.76*(1+Reajustes!H50) | F46: =967.6*(1+Reajustes!H50) | G46: =967.6*(1+Reajustes!H50) | H46: =967.6*(1+Reajustes!H50) | I46: =2120.59*(1+Reajustes!H50) | J46: =967.6*(1+Reajustes!H50) | K46: =961.1*(1+Reajustes!H50) | L46: =961.1*(1+Reajustes!H50) | M46: =961.1*(1+Reajustes!H50) | N46: =1231.75*(1+Reajustes!H50) | O46: =SUM(C46:N46)
...

Sheet Resumo Assembleia
B2: PREVISÃO ORÇAMENTÁRIA 2026
B3: Condomínio Naturale Residencial — Base: Realizado Superlógica
B5: RESUMO FINANCEIRO 2026
C7: Despesa Operacional Anual (base do rateio)
C8: ='Previsao Anual'!E122
C10: Fundo de Reserva (5%) — fora do rateio
C11: =C8*0.05
C13: Total a Ratear no Ano (apenas operacional)
C14: =C8
B17: MODO DE RATEIO
C19: Modo de cálculo: | D19: Fração Ideal
C21: Apartamentos: | D21: 0
C22: Coberturas: | D22: 0
C23: Fator da Cobertura: | D23: 1.5
C24: Total de Unidades (igualitário): | D24: 0
C25: Soma das Frações (deve fechar 1 ou 100%): | D25: =SUM('Frações'!C2:C100000)
C27: Unidades Equivalentes: | D27: =D21+D22*D23
C29: Despesa Mensal a Ratear: | D29: =C14/12
B31: TAXA MENSAL RESULTANTE
C33: Taxa Mensal Média por Unidade: | D33: =IFERROR(IF(D19="Unidades Equivalentes",D29/D27,IF(D19="Igualitário",D29/D24,D29/264)),0)
C34: Taxa Mensal por Cobertura: | D34: =IFERROR(IF(D19="Unidades Equivalentes",D33*D23,D33),0)
C36: No modo Fração Ideal, a taxa de cada unidade = Despesa Mensal × Fração da unidade. Veja a aba 'Frações' (uma linha por unidade).
B40: CUSTO MENSAL POR CATEGORIA
C41: Categoria | D41: Anual (R$) | E41: Mensal (R$)
C42: Despesas Financeiras | D42: ='Previsao Anual'!E12 | E42: =D42/12
C43: Despesa com Funcionários | D43: ='Previsao Anual'!E18 | E43: =D43/12
C44: Retenções Fiscais | D44: ='Previsao Anual'!E23 | E44: =D44/12
C45: Despesa Administrativa | D45: ='Previsao Anual'!E36 | E45: =D45/12
C46: Manutenção | D46: ='Previsao Anual'!E48 | E46: =D46/12
C47: Aquisição de Materiais | D47: ='Previsao Anual'!E71 | E47: =D47/12
C48: Serviços | D48: ='Previsao Anual'!E108 | E48: =D48/12
C49: Investimento e Equipamentos | D49: ='Previsao Anual'!E116 | E49: =D49/12
C50: Taxas e Recolhimentos | D50: ='Previsao Anual'!E120 | E50: =D50/12
C51: TOTAL GERAL | D51: =SUM(D42:D50) | E51: =D51/12

Sheet Frações
B1: Unidade | C1: Fração | D1: Taxa Mensal (R$)
B2: Apto 0101-1 | C2: 0.004226 | D2: ='Resumo Assembleia'!D29*C2
B3: Apto 0102-1 | C3: 0.004226 | D3: ='Resumo Assembleia'!D29*C3
B4: Apto 0103-1 | C4: 0.003388 | D4: ='Resumo Assembleia'!D29*C4
B5: Apto 0104-1 | C5: 0.003201 | D5: ='Resumo Assembleia'!D29*C5
B6: Apto 0105-1 | C6: 0.004226 | D6: ='Resumo Assembleia'!D29*C6
B7: Apto 0106-1 | C7: 0.004226 | D7: ='Resumo Assembleia'!D29*C7
B8: Apto 0107-1 | C8: 0.003201 | D8: ='Resumo Assembleia'!D29*C8
B9: Apto 0108-1 | C9: 0.003388 | D9: ='Resumo Assembleia'!D29*C9
B10: Apto 0201-1 | C10: 0.004226 | D10: ='Resumo Assembleia'!D29*C10
B11: Apto 0202-1 | C11: 0.004226 | D11: ='Resumo Assembleia'!D29*C11
B12: Apto 0203-1 | C12: 0.003388 | D12: ='Resumo Assembleia'!D29*C12
B13: Apto 0204-1 | C13: 0.003201 | D13: ='Resumo Assembleia'!D29*C13
B14: Apto 0205-1 | C14: 0.004226 | D14: ='Resumo Assembleia'!D29*C14
B15: Apto 0206-1 | C15: 0.004226 | D15: ='Resumo Assembleia'!D29*C15
B16: Apto 0207-1 | C16: 0.003201 | D16: ='Resumo Assembleia'!D29*C16
B17: Apto 0208-1 | C17: 0.003388 | D17: ='Resumo Assembleia'!D29*C17
B18: Apto 0301-1 | C18: 0.004226 | D18: ='Resumo Assembleia'!D29*C18
B19: Apto 0302-1 | C19: 0.004226 | D19: ='Resumo Assembleia'!D29*C19
B20: Apto 0303-1 | C20: 0.003388 | D20: ='Resumo Assembleia'!D29*C20
B21: Apto 0304-1 | C21: 0.003201 | D21: ='Resumo Assembleia'!D29*C21
B22: Apto 0305-1 | C22: 0.004226 | D22: ='Resumo Assembleia'!D29*C22
B23: Apto 0306-1 | C23: 0.004226 | D23: ='Resumo Assembleia'!D29*C23
B24: Apto 0307-1 | C24: 0.003201 | D24: ='Resumo Assembleia'!D29*C24
B25: Apto 0308-1 | C25: 0.003388 | D25: ='Resumo Assembleia'!D29*C25
B26: Apto 0401-1 | C26: 0.004226 | D26: ='Resumo Assembleia'!D29*C26
B27: Apto 0402-1 | C27: 0.004226 | D27: ='Resumo Assembleia'!D29*C27
B28: Apto 0403-1 | C28: 0.003388 | D28: ='Resumo Assembleia'!D29*C28
B29: Apto 0404-1 | C29: 0.003201 | D29: ='Resumo Assembleia'!D29*C29
B30: Apto 0405-1 | C30: 0.004226 | D30: ='Resumo Assembleia'!D29*C30
B31: Apto 0406-1 | C31: 0.004226 | D31: ='Resumo Assembleia'!D29*C31
B32: Apto 0407-1 | C32: 0.003201 | D32: ='Resumo Assembleia'!D29*C32
B33: Apto 0408-1 | C33: 0.003388 | D33: ='Resumo Assembleia'!D29*C33
B34: Apto 0501-1 | C34: 0.004226 | D34: ='Resumo Assembleia'!D29*C34
B35: Apto 0502-1 | C35: 0.004226 | D35: ='Resumo Assembleia'!D29*C35
B36: Apto 0503-1 | C36: 0.003388 | D36: ='Resumo Assembleia'!D29*C36
B37: Apto 0504-1 | C37: 0.003201 | D37: ='Resumo Assembleia'!D29*C37
B38: Apto 0505-1 | C38: 0.004226 | D38: ='Resumo Assembleia'!D29*C38
B39: Apto 0506-1 | C39: 0.004226 | D39: ='Resumo Assembleia'!D29*C39
B40: Apto 0507-1 | C40: 0.003201 | D40: ='Resumo Assembleia'!D29*C40
...

Sheet Notas (Por Fora)
B2: ITENS POR FORA DO RATEIO
B3: Itens que NÃO entram no cálculo da taxa condominial. Aparecem como nota na apresentação da assembleia, para total transparência.
B5: Item | C5: Categoria de Origem | D5: Total Anual (R$) | E5: Motivo
B6: Empréstimo Energia Solar | C6: Despesas Financeiras | D6: 89430.96 | E6: Financiamento com prazo definido, custeado por arrecadação específica.
B7: Energia | C7: Consumo e Taxas | D7: 28144.74 | E7: Rateado separadamente (medição/cobrança individual).
B8: Telefone | C8: Consumo e Taxas | D8: 3182.24 | E8: Rateado separadamente (medição/cobrança individual).
B9: Telefonia-Internet | C9: Consumo e Taxas | D9: 1299.99 | E9: Rateado separadamente (medição/cobrança individual).
B10: Água-Esgoto | C10: Consumo e Taxas | D10: 369653.27 | E10: Rateado separadamente (medição/cobrança individual).
B11: Materiais Obras-Melhorias | C11: Aquisição de Materiais | D11: 250000 | E11: Obra extraordinária não recorrente (evento único).
B12: TOTAL POR FORA | D12: =SUM(D6:D11)
